Workbook

Sheet 说明
A1: 职业库审查表（2026-10-07 导出）
A3: 数据口径
A4: 抓取样本 3466 条，去重后 2723 条；挂上岗位树 1731 条，未挂上 992 条
A5: 来源：牛企直聘校招单岗页，每个关键词只取搜索第一页；数字是样本数，不是市场岗位数
A6: 单位数 = 挂到该岗位的不同招聘单位数；证据强度：1 家=证据少，2-4 家=一般，5 家及以上=较多
A7: 源文件：/Users/lucky_wang/Documents/codex/xiaogu-career-suite/data/careerdb/（cards.json、edges.json、postings_mapped.jsonl、role_cards/）
A9: 怎么填
A10: 只填黄色列，其余列是库里导出的原始数据，改了不会回写
A11: 岗位审查：逐行看「原始岗位名」是否都属于这个岗位、职责是否对得上，在「审查结论」下拉里选
A12: 样本明细：岗位审查里发现归类问题时，按「挂到的岗位节点」筛选，逐条判断并写「应归到」
A13: 专业连线：判断「这个专业的人去做这个岗位」是否合理
A15: 填写示例（岗位审查）
... A18: 审查进度
A19: 岗位审查：已填结论 | B19: =COUNTA(岗位审查!Q2:Q196) | C19: / 195
A20: 通过 | B20: =COUNTIF(岗位审查!Q2:Q196,"通过")
A21: 归类有误 | B21: =COUNTIF(岗位审查!Q2:Q196,"归类有误")
A22: 应拆分 | B22: =COUNTIF(岗位审查!Q2:Q196,"应拆分")
A23: 应合并 | B23: =COUNTIF(岗位审查!Q2:Q196,"应合并")
A24: 证据不足 | B24: =COUNTIF(岗位审查!Q2:Q196,"证据不足")
A25: 删除 | B25: =COUNTIF(岗位审查!Q2:Q196,"删除")
A26: 待定 | B26: =COUNTIF(岗位审查!Q2:Q196,"待定")
A27: 样本明细：已判断 | B27: =COUNTA(样本明细!M2:M2724) | C27: / 2723
A28: 专业连线：已判断 | B28: =COUNTA(专业连线!J2:J893) | C28: / 892

Sheet 岗位审查
A1: 序号 | B1: 行业 | C1: 类别 | D1: 岗位 | E1: 节点来源 | F1: 优先级 | G1: 样本数 | H1: 单位数 | I1: 证据强度 | J1: 原始岗位名（出现次数） | K1: 学历分布 | L1: 专业分布 | M1: 职责原文（前3条） | N1: 岗位卡阶段 | O1: 岗位卡缺口 | P1: 示例链接 | Q1: 审查结论 | R1: 问题说明 | S1: 修正建议
A2: 1 | B2: 医疗健康 | C2: 医生/医技 | D2: 临床医生（科室未细分） | E2: 招聘样本补充 | G2: 184 | H2: 120 | I2: =IF(H2<2,"证据少",IF(H2<5,"一般","较多")) | J2: 临床医师9、医师5、病理医师5、中医医师4、口腔医师4、临床医生4、精神科医师3、康复医师3、超声医学科医师3、公卫医师3、中医科医师2、保健医生2、精神科医生2、麻醉医生2、中医|针推医生2、兽医师2、医学影像科医师2、临床医学研究员（非实验岗）2、影像医师2、麻醉医师2、营养科医师2、放射诊断科医师2、放射影像科医师1、校招-临床医师（妇产科）（合肥）J536921、耳鼻喉医师-2027届高校毕业生1、临床医学1、眼科住院医生1、临床检验诊断医师1、手术麻醉医师-2027届高校毕业生1、中医科医师(J20530)1、医师|科研岗1、针灸科医生1、中医骨科医师1、康复科医生（2027届）-厦门鹭园1、妇科门诊医师1、心理科医师1、宠物资深医生1、智能医生体验店经营岗集团管培生1、精神科医师（2027年校招）1、2027-超声医师岗(J20983)1、校招-临床医师（耳鼻咽喉科）（北京）J544781、住院医师（27校招岗）1、康复医生1、2027-口腔医师岗(J20984)1、儿科规培医生1、医师岗位|医技岗位|护理岗位|科研岗位|管理岗位及其他专技1、内科执业医生1、临床医师（急诊医学科）（成都）J537071、康复科医生（2027届）-桂园医院1、急诊医学科医师|重症医学科医师1、校招-临床医师（眼科）（成都）J537101、临床医生（2027校招）1、耳鼻咽喉科住院医师(J10840)1、临床医师（重症医学科）（成都）J537021、轻医美大注射医生1、骨科主治医师1、麻醉手术科医师11、2027-病理医师岗(J20979)1、临床医学医师1、整形医生1、麻醉手术科医师21、校招-临床医师（超声医学科）（苏州）J537241、规范化培训住院医师1、医美医师1、内分泌科医师1、耳鼻咽喉科医生1、校招-临床医师（重症医学科）（合肥）J536991、医学影像医师1、2026招聘医师1、全科医疗科医师1、校招-临床医师（心脏大血管外科）（合肥）J536911、核医学中心医师1、重症医学科医师1、康复科医生(J21157)1、全科医学科医师（2027年校招）1、儿科规培医师|儿外科规培医师1、睡眠与脑医学中心医师1、临床医师岗1、妇女保健医师1、校招-临床医师（康复医学科）（成都）J537141、精神科医师11、精神科医师21、口腔医师岗1、预防保健医生1、麻醉手术科医师(J20507)1、耳鼻喉医师1、外科临床医师1、2027-皮肤性病科医师岗(J20974)1、校招-临床医师（妇产科）（北京）J544761、康复医师(J20517)1、康复医学医师1、妇科医师-2027届高校毕业生1、医学影像医生1、中医助理医师1、2027-麻醉医师岗(J20982)1、骨科医生1、影像科住院医师1、校招-临床医师（眼科）（北京）J544771、校招-临床医师（健管中心体检）（合肥）J536901、口腔执业医师（正畸方向）1、临床医师（骨科）（合肥）J536891、麻醉与围术期医学科麻醉医师20271、精神科住院医师1、校招-临床医师（眼科）（合肥）J536951、康复医学科医师1、皮肤性病科医师(J20519)1、宫颈科主治医师1、CCU医生1、超声医学科诊断医师(2027年校招)1、临床医学应届毕业生1、健康管理部医师1、临床医师（放射科）（北京）J544831、兽医师-江西省1、硕士口腔医师1、放射|超声医师岗1、儿科儿保医生（三甲专硕规培）1、精神科医师岗1、临床医师（病理科）（北京）J544821、预防保健科医生1、妇科病房医师1、中医师1、青年医生医助1、皮肤及整形科医师1、2027-影像医师岗(J20981)1、校招-临床医师（麻醉科）（成都）J537131、病理医生1、校招-临床医师（超声科）（合肥）J536971、影像科医生(J21156)1、推拿医生1、烧伤整形科医师(J20511)1、之家-全国-医生1、校招-临床医师（营养科）（北京）J544801、儿科住院医师(J10447)1、精神心理医师1、中医科针推医师1、针灸医生1、2027届应届临床医师1、超声影像科医师1、临床医师（校招）1 | K2: 硕士97、本科46、博士18、未写16、字段与正文不一致7 | L2: 临床医学类104、不限专业15、社会学类15、基础医学类11、口腔医学类10、中医学类9、医学技术类5、公共卫生与预防医学类4、药学类2、护理学类2、教育学类2、中药学类1、工商管理类1、统计学类1 | M2: 住院医师在上级医师指导和授权下，负责日常的诊疗工作 小时内完成住院病历书写 及时了解所管病人每日的病情和体征变化并充分了解检验检查结果 | N2: 未建卡 | P2: https://campus.niuqizp.com/job-v885CZZza.html
A3: 2 | B3: 医疗健康 | C3: 生物医药 | D3: 科研岗（博士后/研究助理） | E3: 招聘样本补充 | F3: P1 | G3: 162 | H3: 149 | I3: =IF(H3<2,"证据少",IF(H3<5,"一般","较多")) | J3: 博士后35、博士后研究人员17、科研助理11、2026招聘博士后人员6、教学科研人员4、博士后研究员3、研究助理3、生物反应器研发科研助理2、专职科研人员2、教学科研2、2026招聘博士后研究人员2、博士后|科研助理2、博士后|副研究员2、分析表征研究助理2、儿科博士后1、生物信息学实验室 AI和数据分析方向的博士后|分子生物学方向的博士后1、运营实习生,职业教育编辑,事业发展部负责人,文字编辑,校对质检编辑,全职营销编辑,实习编辅,版权贸易干事,大众编辑部主任,医学编辑部主任,医学编辑,策划编辑,大众读物编辑室副主任,图书编辑,网络文学编辑,营销编辑,博士后研究人员,翻译研究部研究岗,文化交流部专项工作岗,财务管理部会计岗,当代世界出版社办公室（总编室）,编辑部,发行部,营销宣传部实习岗,人力资源部实习生,编辑运营岗,项目助理实习生,直播助理实习生,高级编辑,编辑助理1、师资博士后1、项目博士后1、生物信息学|数据分析方向博士后1、免疫方向博士后|生物信息学方向博士后|科研助理1、皮肤科治疗技师|影像科技师|骨科生物力学实验室研究助理1、生物智能科研助理1、营养与食品安全方向初级研究助理1、准聘副教授|准聘教授|长聘教授|博士后1、财务处出纳|西餐烹饪工艺教学科研岗|教学秘书1、公文管理助理岗|调查研究助理岗|信息咨政助理岗1、中国古代文学博士后岗位1、科研助理31、博士后-农业生态水文与节水方向1、张永振课题组科研助理1、实验室管理员|分子生物学技术员|生物信息分析师|博士后1、临床|科研型博士后1、肠道菌群方向博士后1、博士后工作站-人工智能在核酸药物开发及应用方向1、医疗大数据挖掘方向博士后1、博士后人员1、水质与水生态研究中心水污染控制的绿色过程方向科研助理51、健康大数据科研助理1、基础医学博士后1、科研人员1、城市人因研究科研助理21、量化与AI应用方向经济学研究助理1、科研助理51、电子源材料与器件研究方向专职科研人员1、人工智能在生物学大数据应用方向博士后研究人员1、2026招聘博士后1、2026招聘中国史博士后岗位1、鲁棒统计学习与因果推断研究方向博士后1、科研型博士后1、AI医学影像博士后1、生物医学工程方向研究助理1、副研究员|助理研究员|博士后|AI|算法工程师1、科研助理岗91、（多模态医学数据分析团队） 博士后1、博士后|实验技术人员|科研助理|项目研究人员1、儿内科临床型博士后1、生物技术学院课题组临床转化研究助理岗位1、生物信息学分析师|科研助理1、乳品微生物|营养与流行病方向科研助理1、科研助理|研究实习员1、临床型博士后|科研型博士后1、分子生物学研究员（博士）/联合博士后1、教研人员|博士后1、教育学博士后研究人员1、比较文学与世界文学博士后岗位1、71名博士后1、创意写作博士后1、管理助理|研究助理1、特别研究助理1、至臻博士后|A类博士后|B类博士后1、中国财政与税收研究所科研助理岗21、临床型博士后1、课题组科研助理21、电子信息材料与器件研究部博士后1、领军人才|学术带头人|优秀副研究员|博士后1、临床前研究助理1、2026招聘教学科研人员1、儿外科临床型博士后1、建筑遗产保护科研助理1、生物医学工程方向博士后1、全职博士后1、博士后岗位（心理学领域）1 | K3: 博士99、本科21、硕士20、未写14、字段与正文不一致7、大专1 | L3: 生物科学类30、计算机类23、基础医学类18、临床医学类17、统计学类13、经济学类11、药学类10、金融学类9、化学类8、心理学类8、社会学类7、新闻传播学类6、教育学类5、建筑类4、管理科学与工程类4、历史学类4、生物医学工程类4、法学类3、工商管理类3、医学技术类3、食品科学与工程类3、中医学类3、不限专业3、公共卫生与预防医学类3、生物工程类2、电子信息类2、电气类2、材料类2、物理学类2、公共管理类2、中国语言文学类2、自动化类2、旅游管理类2、财政学类2、外国语言文学类1、植物生产类1、护理学类1、数学类1、土木类1、环境科学与工程类1、口腔医学类1、机械类1、交通运输类1 | M3: 科研助理（生物反应器研发） 岗位职责 1.积极开展课题设计，完成相关实验、数据分析和论文撰写 完成合作导师交予的其他科研相关事务 | N3: jd_only_draft | O3: 从业者一手分享：未找到可入卡的已核正文，缺2名不同作者 日常体验、考核指标、发展路径与条件化风险：缺从业者证据，不用招聘宣传补齐 未抽出职责句，plain_language与daily_work留空 招聘正文样本不足3：当前0份；联网补抓未执行 可核职责少于4条，不凑数 | P3: https://campus.niuqizp.com/job-v885t5aCC.html
A4: 3 | B4: 教育培训 | C4: 教师 | D4: 教师 | E4: BOSS分类 | F4: P2 | G4: 63 | H4: 48 | I4: =IF(H4<2,"证据少",IF(H4<5,"一般","较多")) | J4: 思政教师5、体育教师5、骨干教师岗位3、教师3、入户早教师2、高等学校教师2、历史教师2、学前教育专业教师2、中草药栽培教师1、小学教育教师1、初高中体育教师1、哲学系外国哲学|中国哲学教师1、教学系列教师1、电气专业教师1、高中政治教师1、2026招聘小学素质类教师1、幼儿部--双语教师、外籍教师1、思想政治理论课教师1、材料科学与工程教师岗位1、计算机专业教师1、幼儿园编制教师1、心理健康教育教师1、法学教师1、学前教育教师1、国际部高中--IGCSE/A-LEVEL 双语（经济、数学、物理、化学、生物）教师1、农业机械化教师1、植物保护教师1、高中体育教师1、园艺教师1、康复训练教师1、早教师1、2026招聘教师1、拔尖人才|青年英才|骨干教师1、高中历史教师1、园林教师1、2026招聘国际中文教师1、2027招聘文科中学授课教师|理科中学授课教师1、技术教师（工作地：海南澄迈）（济南）1、信息工程教师岗位1、大语文|数学思维|双语教师管培生1、中药学教师1、国际中文教育教师1、教师岗位1、旅游管理专业教师1、建筑技术方向教师岗位1、对外汉语教师1、汉语教师 （小班教学 欧美学生）1 | K4: 硕士24、本科14、博士11、未写7、字段与正文不一致5、大专2 | L4: 教育学类14、计算机类6、不限专业5、心理学类5、管理科学与工程类5、体育学类4、中国语言文学类4、法学类3、历史学类3、药学类2、中药学类2、马克思主义理论类2、经济学类2、工商管理类2、化学类1、化工与制药类1、自动化类1、电气类1、材料类1、社会学类1、新闻传播学类1、护理学类1、医学技术类1、外国语言文学类1、音乐与舞蹈学类1、哲学类1、环境科学与工程类1、统计学类1、旅游管理类1、建筑类1 | M4: 教育/培训/院校 培训及其他：配合完成企业培训工作，开发课程方案、课程教学、攻关企业技术难题等 制订教学计划，认真完成日常的备课授课，进行教学总结 | N4: jd_only_draft | O4: 从业者一手分享：未找到可入卡的已核正文，缺2名不同作者 日常体验、考核指标、发展路径与条件化风险：缺从业者证据，不用招聘宣传补齐 | P4: https://campus.niuqizp.com/job-v885CzzM5.html
A5: 4 | B5: 教育培训 | C5: 教师 | D5: 高校教师/辅导员 | E5: 招聘样本补充 | F5: P2 | G5: 45 | H5: 39 | I5: =IF(H5<2,"证据少",IF(H5<5,"一般","较多")) | J5: 教授|副教授|讲师15、专任教师5、讲师3、助理教授|预聘副教授|长聘副教授|教授2、助理教授（教研系列）,助理教授（设计系列）,长聘副教授（教研系列）,准聘副教授或长聘副教授1、储备辅导员岗1、辅导员1、排球|田径|乒乓球|网球教学型讲师1、马克思主义学院专任教师1、商务英语类专任教师1、电子商务类专任教师1、博士专任教师1、学科带头人|教授|副教授|讲师1、汉语言文学|汉语国际教育专任教师1、副教授|讲师1、数据科学与大数据技术专任教师1、教授|副教授|讲师|特聘研究员|特聘副研究员1、重点实验室王志华教授课题组技术员1、助理教授A1、专职辅导员|财务岗1、助理教授|高层次人才1、交叉科学方向统计系教研系列助理教授|副教授|教授1、助理教授|副教授|教授1、思政教师|辅导员1 | K5: 博士33、硕士7、未写3、字段与正文不一致2 | L5: 经济学类7、计算机类7、金融学类3、法学类3、社会学类2、不限专业2、材料类2、建筑类1、动物医学类1、新闻传播学类1、电子信息类1、电气类1、机械类1、统计学类1、工商管理类1、心理学类1、哲学类1、教育学类1、林学类1 | M5: 学院国际化办学特色鲜明，与全球顶尖高校、科研机构建立长期深度合作，国际影响力突出 长聘副教授（教研系列）（城乡规划学）：城乡规划与设计 准聘副教授或长聘副教授（建筑环境与能源应用工程）：建筑能源系统优化设计与智能控制 | N5: jd_only_draft | O5: 从业者一手分享：未找到可入卡的已核正文，缺2名不同作者 日常体验、考核指标、发展路径与条件化风险：缺从业者证据，不用招聘宣传补齐 | P5: https://campus.niuqizp.com/job-v8Y5zaLLn.html
A6: 5 | B6: 医疗健康 | C6: 生物医药 | D6: 医疗产品技术支持 | E6: BOSS分类 | F6: P1 | G6: 41 | H6: 37 | I6: =IF(H6<2,"证据少",IF(H6<5,"一般","较多")) | J6: 应用工程师8、信息化工程师5、临床技术支持专员3、技术支持工程师3、技术支持2、AI应用工程师2、临床技术工程师|临床技术支持专员1、现场应用工程师1、产品技术支持工程师1、医学技术支持1、临床技术支持工程师1、2027届-应用工程师1、大模型应用工程师1、检验线技术支持工程师1、技术支持专员(J12042)1、临床技术支持1、食品技术支持1、仪器应用工程师1、应用工程师（通用）--上海/成都1、项目管理岗|资源开发岗|技术支持岗1、应用工程师-计算光刻（北京）1、IT与AI应用工程师1、开发应用工程师1、无锡区公司-AI应用工程师1 | K6: 本科23、硕士12、未写2、字段与正文不一致2、大专2 | L6: 不限专业11、计算机类6、基础医学类5、临床医学类5、电子信息类4、机械类4、材料类3、化学类3、化工与制药类3、数学类3、物理学类2、医学技术类2、食品科学与工程类2、自动化类2、生物医学工程类1、药学类1、统计学类1、生物工程类1、电气类1、管理科学与工程类1、环境科学与工程类1、教育学类1、生物科学类1、植物生产类1 | M6: 为客户提供化学驱油剂（如聚合物、表面活性剂、碱驱剂等）的应用指导与调试服务 向客户（油田技术团队、作业人员）讲解产品性能、作用机理及操作规范，提供技术培训 收集现场反馈，联动研发团队改进产品配方与应用工艺 | N6: jd_only_draft | O6: 从业者一手分享：未找到可入卡的已核正文，缺2名不同作者 日常体验、考核指标、发展路径与条件化风险：缺从业者证据，不用招聘宣传补齐 | P6: https://campus.niuqizp.com/job-v8U5Nn55z.html
A7: 6 | B7: 人力/行政/法务 | C7: 行政 | D7: 行政专员/助理 | E7: BOSS分类 | F7: P2 | G7: 39 | H7: 35 | I7: =IF(H7<2,"证据少",IF(H7<5,"一般","较多")) | J7: 行政管理岗5、行政管理人员5、行政助理3、生物医学科学行政专员2、宣传公关行政助理1、经济金融及统计类岗位|法律类岗位|财务会计类岗位|综合管理类岗位1、国际教育学院行政管理岗位1、生物学高层次人才培养项目行政助理岗1、医务部行政管理1、教务处培养与专业建设办公室行政管理人员1、综合管理岗1、行政管理专员1、综合管理部后勤保障岗|学术科教部干事岗1、2026招聘工程技术岗|战新产业岗|财务管理岗|外语翻译岗|法律咨询岗|行政管理岗1、综合管理岗|MPA项目综合管理岗1、课题组行政助理1、财税研究所行政管理岗1、行政管理1、综合管理部行政事务岗1、行政管理岗位1、科研行政管理1、教学及学生事务行政专员1、学生行政助理1、综合管理岗位1、行政助理岗1、课题组行政助理岗1、金融财会类岗位|综合管理类岗位1、综合管理岗位01|综合管理岗位02|综合管理岗位03|综合管理岗位041 | K7: 本科20、硕士12、未写4、博士3 | L7: 工商管理类5、生物科学类4、管理科学与工程类4、经济学类3、公共卫生与预防医学类3、计算机类3、金融学类2、不限专业2、中国语言文学类2、法学类2、社会学类2、教育学类2、基础医学类1、临床医学类1、口腔医学类1、中医学类1、药学类1、中药学类1、护理学类1、公共管理类1、土木类1、交通运输类1、马克思主义理论类1、历史学类1 | M7: 完成宣传手册、招生简章、折页等印刷材料的文字编辑与校对 完成上级分配的其他相关任务 负责生物学高层次人才培养项目相关行政事务 | N7: jd_only_draft | O7: 从业者一手分享：未找到可入卡的已核正文，缺2名不同作者 日常体验、考核指标、发展路径与条件化风险：缺从业者证据，不用招聘宣传补齐 | P7: https://campus.niuqizp.com/job-v885zMCNM.html
A8: 7 | B8: 高级管理 | C8: 高级管理职位 | D8: 管理培训生 | E8: 招聘样本补充 | F8: P2 | G8: 36 | H8: 13 | I8: =IF(H8<2,"证据少",IF(H8<5,"一般","较多")) | J8: 物流网络管理培训生2、2027级管理培训生（投资类）1、2027级管理培训生（监察审计类）1、财务管理岗GXZX/管理培训生1、人力资源管理岗ZXLY/管理培训生1、新能源技术监督工程(风电控制方向)JSYJY/管理培训生1、市场营销岗HNSD/管理培训生1、财务管理岗DBSY/管理培训生1、财务管理岗DBXNY/管理培训生1、管理培训生-物流运营1、2027级管理培训生（精算类）1、管理培训生-北苑酒店1、土建管理工程师XJBZ/管理培训生1、2026招聘管理培训生1、热控工程师HZEXB/管理培训生1、安全监督工程师XJXJ/管理培训生1、管理培训生|健康顾问|营养师1、财务管理岗XJXJ/管理培训生1、财务管理岗XJBZ/管理培训生1、人力资源管理岗XJBZ/管理培训生1、总行管理培训生/法律人才专项招聘1、2027级管理培训生（核保核赔类）1、管理培训生-核保方向（所属河北分公司）1、热控工程师XJCN/管理培训生1、财务管理岗HBJJJ/管理培训生1、行政后勤管理岗XJXJ/管理培训生1、集控系统研发工程师JSYJY/管理培训生1、研发技术管理培训生1、人力资源管理岗XJXJ/管理培训生1、综合事务岗XJBZ/管理培训生1、财务管理岗XJCN/管理培训生1、热控工程师DBGC/管理培训生1、管理培训生1、管理培训生-福建分公司1、金融理财顾问方向管理培训生1 | K8: 本科25、硕士11 | L8: 不限专业15、工商管理类6、金融学类3、法学类2、物流管理与工程类2、数学类2、电气类2、能源动力类1、公共管理类1、马克思主义理论类1、新闻传播学类1、计算机类1、环境科学与工程类1、生物工程类1、食品科学与工程类1、电子商务类1、统计学类1、自动化类1、中国语言文学类1、药学类1、心理学类1、经济学类1 | M8: 参与股权投资项目的投前尽调、投后管理和退出工作 协助对子公司战略规划、风险管理和财务等工作提供支持 参与委托投资管理和资产配置执行工作 | N8: jd_only_draft | O8: 从业者一手分享：未找到可入卡的已核正文，缺2名不同作者 日常体验、考核指标、发展路径与条件化风险：缺从业者证据，不用招聘宣传补齐 | P8: https://campus.niuqizp.com/job-v8Y5nLzzt.html
A9: 8 | B9: 医疗健康 | C9: 医疗销售 | D9: 医药代表 | E9: BOSS分类 | F9: P1 | G9: 33 | H9: 25 | I9: =IF(H9<2,"证据少",IF(H9<5,"一般","较多")) | J9: 医药代表8、医学信息沟通专员4、医学信息沟通专员（医药代表）3、医药信息沟通专员2、医学信息沟通管培生1、27届医学信息沟通专员1、2027招聘临床学术专员1、实习医药代表（上海）1、医药代表实习生1、医学信息沟通代表实习生-温州-肠内营养事业部 (MJ000678)1、医学信息沟通代表实习生-台州-肠内营养事业部 (MJ000676)1、医学信息沟通代表实习生-福州-肠内营养事业部 (MJ000679)1、医药代表|学术专员1、医学信息沟通管培生（江西省可分配）1、医学信息沟通代表实习生-宁波-肠内营养事业部 (MJ000677)1、临床代表|医药代表1、医药代表实习生-大连-R28646141、医药代表实习生（扬州）1、医学信息沟通代表实习生-合肥-肠内营养事业部 (MJ000681)1、医学信息沟通代表实习生-盐城-肠内营养事业部 (MJ000680)1 | K9: 本科21、大专8、字段与正文不一致3、未写1 | L9: 不限专业12、药学类12、基础医学类4、临床医学类4、护理学类3、生物工程类2、生物科学类1、化工与制药类1、工商管理类1、食品科学与工程类1 | M9: 负责所在区域的销售工作，与顾客面对面的交谈,介绍产品,让顾客体验产品，完成签单 维护老客户，开拓新市场，发现新客户，拓展业务范围 服从工作安排，配合销售市场部的相关工作 | N9: jd_only_draft | O9: 从业者一手分享：未找到可入卡的已核正文，缺2名不同作者 日常体验、考核指标、发展路径与条件化风险：缺从业者证据，不用招聘宣传补齐 | P9: https://campus.niuqizp.com/job-v8U5MMtNN.html
A10: 9 | B10: 医疗健康 | C10: 医生/医技 | D10: 医学技师（影像/放疗/导管等） | E10: 招聘样本补充 | G10: 32 | H10: 28 | I10: =IF(H10<2,"证据少",IF(H10<5,"一般","较多")) | J10: 检验技师4、生物医学影像技术中心技术人员2、导管室技师2、医学影像科技师2、耳鼻喉科技师|临床科室护理1、医学影像医师/技师1、医学检验科技师1、病理检验医学部检验技师1、放射技师1、康复医学科技师1、现代康复治疗区康复治疗师|传统康复治疗区推拿技师1、康复治疗技师|健康管理师|影像技师|口腔科技师1、前厅技师|前庭方向听力技师1、产后保健科技师|儿童康复科文员|文员1、放射科技师(J10853)1、康复技师（运动康复方向）1、影像技师1、磁共振室影像技师（2027年校招）1、药剂技师1、放射科技师1、前庭方向听力技师|放射技师|药师1、核医学中心技师1、耳鼻喉科技师|社康康复治疗师1、康复治疗师|传统康复治疗区推拿技师1、嗓音耳鼻咽喉头颈外科技师|听力耳鼻咽喉头颈外科技师|口腔科放射技师1、产后康复师|放射影像科技师1 | K10: 本科22、硕士5、博士3、未写2 | L10: 医学技术类18、临床医学类10、基础医学类4、生物医学工程类1、不限专业1、药学类1、化学类1、教育学类1、社会学类1 | M10: 负责医院OCT、AB超、眼底造影等临床医学影像检查与诊断工作 负责医学影像设备的日常维护与保养工作 认真执行各项规章制度和技术操作规程 | N10: 未建卡 | P10: https://campus.niuqizp.com/job-v885Zttnn.html
A11: 10 | B11: 医疗健康 | C11: 护士/护理 | D11: 护士 | E11: BOSS分类 | G11: 30 | H11: 28 | I11: =IF(H11<2,"证据少",IF(H11<5,"一般","较多")) | J11: 护士11、护理4、健康管理护士1、医美护士1、2026招聘护理部护士1、之家-赣园康复医院-护士（27届）1、临床护士1、一年制护士（护理志愿者岗）1、2027届护理应届生1、精神科研究生护理岗1、体检|医美中心护理岗1、护士（27届校招）(J10862)1、护理部护士21、京东体检中心护理岗1、护士/护理（英语）1、临床护士（合肥）J537001、护理部护士11 | K11: 本科14、大专9、未写4、硕士3 | L11: 护理学类22、不限专业4、临床医学类3、社会学类1、环境科学与工程类1 | M11: 负责患者的基础护理与专科护理，密切观察病情变化，及时准确执行医嘱 （1）负责健康管理中心各项护理工作，协助心电图、B超等检查工作 （3）负责体检客户引导、咨询工作，维持体检现场秩序 | N11: 未建卡 | P11: https://campus.niuqizp.com/job-v8U5ZaZMC.html
A12: 11 | B12: 影视/传媒 | C12: 采编/写作/出版 | D12: 编辑 | E12: BOSS分类 | F12: P2 | G12: 26 | H12: 25 | I12: =IF(H12<2,"证据少",IF(H12<5,"一般","较多")) | J12: 编辑7、经济管理类教材学术专著策划编辑3、编辑岗2、实习编辑2、英文数字编辑（外研在线）（2027秋季校招）1、科学编辑1、新闻编辑1、舆情编辑1、英文编辑岗1、Bulletin编辑部 科学编辑1、高起点新刊Transformative Chemistry 科学编辑1、医学SCI文章编辑1、《法学杂志》编辑岗1、图书编辑1、媒体制作技术编辑1、专职编辑1 | K12: 硕士9、博士6、未写5、本科4、字段与正文不一致2 | L12: 新闻传播学类4、统计学类4、金融学类3、财政学类3、外国语言文学类3、数学类3、建筑类2、设计学类2、经济学类2、经济与贸易类2、法学类2、工商管理类2、基础医学类2、临床医学类2、历史学类1、生物科学类1、计算机类1、美术学类1、音乐与舞蹈学类1 | M12: （4）资源维护：开发并维护好跟作者、绘者等合作机构的良好合作关系 有意者请以【应聘实习编辑】应聘者姓名为邮件标题，将简历以附件形式发至 善于沟通，适应团队合作，有责任心、行动力，做事认真、细心，能够整合信息，逻辑缜密 | N12: jd_only_draft | O12: 从业者一手分享：未找到可入卡的已核正文，缺2名不同作者 日常体验、考核指标、发展路径与条件化风险：缺从业者证据，不用招聘宣传补齐 | P12: https://campus.niuqizp.com/job-v8l5ZzLzn.html
A13: 12 | B13: 互联网/AI | C13: 后端开发 | D13: 软件开发工程师（未细分） | E13: 招聘样本补充 | F13: P2 | G13: 25 | H13: 24 | I13: =IF(H13<2,"证据少",IF(H13<5,"一般","较多")) | J13: 软件工程师10、软件开发工程师3、软件开发1、应用软件工程师1、ai软件工程师1、图像处理算法工程师,信号处理算法工程师,AI算法工程师,应用软件工程师,光机结构工程师,电源工程师,嵌入式硬件工程师,产品验证工程师,机械工程师,全球技术支持工程师1、应用软件工程师（地点 武汉）1、软件工程师（地点 武汉）1、信号处理应用软件开发工程师1、软件开发工程师,数据分析师,产品经理,UI,UX设计师,算法工程师,运维工程师,医学内容编辑,客户成功经理,市场推广专员,人力资源专员1、高级高压系统工程师,高级车载能源工程师,高级底盘工程师,高级产品设计工程师,高级CAE工程师,高级车身集成工程师,高级造型设计师,高级整车集成工程师,高级车型成本分析工程师,高级前瞻模具工程师,编程工程师,高级软件工程师1、生物实验工程师|上位机软件工程师1、应用/软件工程师（汽车）1、嵌入式软件工程师1 | K13: 硕士11、本科11、未写3 | L13: 计算机类13、不限专业5、机械类5、自动化类4、材料类4、电气类3、生物医学工程类2、数学类2、统计学类2、物理学类2、基础医学类1、教育学类1、法学类1、管理科学与工程类1、交通运输类1、物流管理与工程类1、工商管理类1、设计学类1、美术学类1、电子信息类1 | M13: 负责项目的软件开发与维护工作 参与项目技术文档的编写工作 参与结构化、高质量数据集建设工作 | N13: jd_only_draft | O13: 从业者一手分享：未找到可入卡的已核正文，缺2名不同作者 日常体验、考核指标、发展路径与条件化风险：缺从业者证据，不用招聘宣传补齐 | P13: https://campus.niuqizp.com/job-v8U5aZ5CN.html
A14: 13 | B14: 生产制造 | C14: 机械设计/制造 | D14: 机械工程师 | E14: BOSS分类 | F14: P2 | G14: 24 | H14: 23 | I14: =IF(H14<2,"证据少",IF(H14<5,"一般","较多")) | J14: 机械设计工程师9、机械工程师6、机械设计2、2027届-机械工程师1、机械设计工程师(J10807)1、机械设计（助理）工程师1、自动化管培生-机械设计方向1、机器人方向机械设计工程师1、机械设计（地点 武汉）1、结构设计工程师|结构设计工程师助理1 | K14: 本科14、硕士7、字段与正文不一致1、大专1、未写1 | L14: 机械类11、不限专业7、设计学类5、自动化类3、电气类2、能源动力类1、计算机类1、土木类1 | M14: 参与机器人集成工作站的需求梳理和结构方案设计 协助完成三维建模、2D工程图输出和BOM选型 参与设备加工装配、测试验证和现场安装调试 | N14: jd_only_draft | O14: 从业者一手分享：未找到可入卡的已核正文，缺2名不同作者 日常体验、考核指标、发展路径与条件化风险：缺从业者证据，不用招聘宣传补齐 | P14: https://campus.niuqizp.com/job-v8m5MCCZn.html
A15: 14 | B15: 互联网/AI | C15: 人工智能 | D15: 算法工程师 | E15: BOSS分类 | F15: P1 | G15: 23 | H15: 20 | I15: =IF(H15<2,"证据少",IF(H15<5,"一般","较多")) | J15: 算法工程师6、图像算法工程师3、图像与图谱算法工程师（地点 宜昌）1、图像处理算法工程师超声,图像处理算法工程师内镜,信号处理算法工程师超声,光学工程师,AI算法工程师,材料开发工程师,临床工程师内镜1、医学研究型PM|医用人工智能算法工程师|转移转化与投资经理1、图像算法工程师（AI）1、研发工程师,实施工程师,算法工程师,数据工程师,产品经理,项目经理,业务顾问,客户经理,销售咨询生1、数学应用算法工程师1、人工智能算法工程师1、图像处理/视觉算法工程师1、深度学习图像算法工程师1、图像处理AI方向算法工程师1、系统算法工程师1、控制算法工程师（博士）1、视觉算法工程师1、应用算法工程师1 | K15: 硕士15、本科3、博士3、字段与正文不一致1、未写1 | L15: 计算机类12、数学类5、不限专业4、基础医学类3、自动化类2、生物医学工程类2、临床医学类1、中医学类1、药学类1、生物科学类1、统计学类1、物理学类1、电子信息类1 | M15: 负责CT图像重建算法的设计、实现与优化，持续提升重建速度和图像质量 负责原始投影数据的预处理、校准和校正，分析并解决伪影及成像异常问题 负责算法的性能测试、评估和工程优化，推动算法在CPU/GPU等平台上的高性能实现 | N15: jd_only_draft | O15: 从业者一手分享：未找到可入卡的已核正文，缺2名不同作者 日常体验、考核指标、发展路径与条件化风险：缺从业者证据，不用招聘宣传补齐 | P15: https://campus.niuqizp.com/job-v8U5nLMZL.html
A16: 15 | B16: 市场/公关/广告 | C16: 市场营销 | D16: 市场营销策划 | E16: BOSS分类 | F16: P2 | G16: 22 | H16: 20 | I16: =IF(H16<2,"证据少",IF(H16<5,"一般","较多")) | J16: 市场专员6、市场营销6、市场营销岗4、市场营销专员2、市场营销经理1、电子商务市场专员1、市场营销实习生1、市场专员（实习）1 | K16: 本科12、未写6、硕士2、字段与正文不一致1、大专1 | L16: 不限专业9、工商管理类5、药学类3、经济与贸易类1、旅游管理类1、设计学类1、基础医学类1、电气类1、公共卫生与预防医学类1、医学技术类1、管理科学与工程类1 | M16: 负责代销机构的对接与维护，参与路演活动，提供渠道业务拓展支持服务 负责直销客户的拓展与维护，对接直销工作相关事宜，完善直销工作流程 与渠道及高净值客户建立长期合作关系， 及时沟通反馈渠道及客户相关问题 | N16: jd_only_draft | O16: 从业者一手分享：未找到可入卡的已核正文，缺2名不同作者 日常体验、考核指标、发展路径与条件化风险：缺从业者证据，不用招聘宣传补齐 | P16: https://campus.niuqizp.com/job-v8Y5ztLNL.html
A17: 16 | B17: 医疗健康 | C17: 临床试验 | D17: 医学事务/医学信息 | E17: 招聘样本补充 | F17: P1 | G17: 22 | H17: 19 | I17: =IF(H17<2,"证据少",IF(H17<5,"一般","较多")) | J17: 医学专员9、真实世界研究业务实习生,医药洞察与咨询分析实习生,ETL实习生,医学运营实习生,大模型算法实习生,大模型应用算法实习生,数据分析实习生,大模型医学产品实习生,商务助理实习生,精细化运营BI实习生,财务BP实习生,人力资源实习生2、（高级）医学专员/产品专员2、医学联络员2、临床技术工程师|医学专业精英|医学联络官|产品岗1、MSL医学联络官1、市场|医学专员1、高级/医学专员1、医学信息专员实习生-广州1、技术支持工程师|医学专员1、医学联络员（MSL)1 | K17: 硕士10、本科9、博士1、字段与正文不一致1、未写1 | L17: 临床医学类13、药学类9、不限专业4、生物医学工程类3、基础医学类2、公共卫生与预防医学类2、生物科学类2、公共管理类2、经济学类2、计算机类2、数学类2、统计学类2、工商管理类2、中医学类1、医学技术类1、护理学类1 | M17: 参与项目初期调研、方案设计阶段相关工作 参与项目申报、监管沟通等相关工作 参与临床实施项目的医学支持工作：方案解读与培训，相关文件撰写，医学沟通等 | N17: jd_plus_scoped_practitioners | O17: 本人分享仅覆盖细分子类：医学事务为MSL，图像算法为CT物理算法；不提升整个混合节点为full | P17: https://campus.niuqizp.com/job-v885NtCMN.html
A18: 17 | B18: 医疗健康 | C18: 医生/医技 | D18: 外科医生 | E18: BOSS分类 | G18: 20 | H18: 18 | I18: =IF(H18<2,"证据少",IF(H18<5,"一般","较多")) | J18: 外科医师8、外科医师岗2、外科医生1、口腔外科医生1、普通外科医师1、耳鼻咽喉头颈外科医师1、2027-普外科医师岗(J20966)1、泌尿外科医师1、外科医师-2027届高校毕业生1、2026招聘外科医生1、神经外科医师助理1、小儿外科医师1 | K18: 硕士13、未写3、本科1、博士1、大专1、字段与正文不一致1 | L18: 临床医学类14、基础医学类3、不限专业1、社会学类1、教育学类1、口腔医学类1 | M18: 负责临床医师日常诊疗及科研工作 严格落实院感防控、医疗核心制度，规范执行各项诊疗操作，杜绝医疗安全隐患 负责外科常见病、多发病的临床诊断、治疗及手术操作，严格执行医疗核心制度 | N18: 未建卡 | P18: https://campus.niuqizp.com/job-v8l5tanaz.html
A19: 18 | B19: 医疗健康 | C19: 医生/医技 | D19: 口腔科医生 | E19: BOSS分类 | G19: 20 | H19: 7 | I19: =IF(H19<2,"证据少",IF(H19<5,"一般","较多")) | J19: 口腔科2、校招-口腔科医师-山东【2027届】1、口腔科医生(J21158)1、校招-口腔科医师-成都【2027届】1、校招-口腔科医师-武汉【2027届】1、口腔科医师1、口腔科医生（2027届）1、校招-口腔科医师-大连【2027届】1、口腔科医师（2027年校招）1、校招-口腔科医师-江苏【2027届】1、口腔科医师(J20508)1、校招-口腔科医师-吉林【2027届】1、校招-口腔科医师-广东【2027届】1、校招-口腔科医师-上海【2027届】1、校招-口腔科医师-昆明【2027届】1、校招-口腔科医师-江西【2027届】1、校招-口腔科医师-浙江【2027届】1、校招-口腔科医师-重庆【2027届】1、校招-口腔科医师-北京【2027届】1 | K19: 本科13、硕士5、大专2 | L19: 口腔医学类18、工商管理类1 | M19: 负责口腔常见病、多发病的诊断与治疗，包括牙体牙髓病、牙周病及简单拔牙等 规范书写门诊病历及医疗文书，确保诊疗记录完整、准确、合规 严格执行无菌操作规范及医院感染控制制度，保障医疗安全 | N19: 未建卡 | P19: https://campus.niuqizp.com/job-v8U5MN5CN.html
A20: 19 | B20: 医疗健康 | C20: 理疗保健 | D20: 营养师/健康管理师 | E20: BOSS分类 | F20: P1 | G20: 20 | H20: 17 | I20: =IF(H20<2,"证据少",IF(H20<5,"一般","较多")) | J20: 健康管理师9、2026招聘健康管理师3、健康管理师|助理健康管理师1、营养师助理1、健康管理师（可实习）1、2026招聘门店健康管理师1、实习营养师——黄山首康1、驻店营养师1、临床营养师1、临床营养师助理1 | K20: 大专13、本科5、未写2 | L20: 基础医学类5、药学类5、不限专业4、护理学类3、医学技术类2、临床医学类2、公共管理类1、公共卫生与预防医学类1、食品科学与工程类1、工商管理类1、中药学类1、社会学类1 | M20: 根据顾客身体情况进行相对应的产品介绍及搭配 跟踪用户健康管理效果，通过数据分析优化服务策略，增强用户粘性 维护客户关系，促进客户满意度和忠诚度 | N20: jd_only_draft | O20: 从业者一手分享：未找到可入卡的已核正文，缺2名不同作者 日常体验、考核指标、发展路径与条件化风险：缺从业者证据，不用招聘宣传补齐 | P20: https://campus.niuqizp.com/job-v885anNMt.html
A21: 20 | B21: 医疗健康 | C21: 临床试验 | D21: 临床监查员 | E21: BOSS分类 | F21: P1 | G21: 19 | H21: 12 | I21: =IF(H21<2,"证据少",IF(H21<5,"一般","较多")) | J21: 临床监查员6、CRA临床监查员3、临床监查员II/III期-厦门 (MJ022455)1、临床监查员II/III期-南京 (MJ022446)1、临床监查员II/III期-南昌 (MJ022436)1、临床监查员II/III期-郑州 (MJ022444)1、临床监查员II/III期-武汉 (MJ022432)1、临床监查员II/III期-长沙 (MJ022434)1、临床监查员CRA（可实习）1、临床监查管培生II/III期-深圳 (MJ022461)1、临床监查员CRA1、临床监查管培生II/III期-郑州 (MJ022452)1 | K21: 本科13、硕士6 | L21: 药学类10、临床医学类8、不限专业8、护理学类5、基础医学类4、中医学类3、公共卫生与预防医学类2、中药学类2、统计学类1、医学技术类1 | M21: 根据公司及部门要求，组织科室宣讲、患者活动以及疾病调查，推进完成项目入组目标 协助研究者完成数据疑问，及时、完整地收集研究相关资料 完成并反馈公司需要收集的各项报告和反馈 | N21: jd_only_draft | O21: 从业者一手分享：未找到可入卡的已核正文，缺2名不同作者 日常体验、考核指标、发展路径与条件化风险：缺从业者证据，不用招聘宣传补齐 | P21: https://campus.niuqizp.com/job-v8r5CaLnZ.html
A22: 21 | B22: 产品 | C22: 产品经理 | D22: 产品经理 | E22: BOSS分类 | F22: P1 | G22: 19 | H22: 19 | I22: =IF(H22<2,"证据少",IF(H22<5,"一般","较多")) | J22: 产品经理12、2026招聘AI应用方向产品经理1、产品经理（校招）1、27届-产品经理1、短期健康保险产品经理1、医学产品经理|医学研究员1、产品经理(J11059)1、生信产品经理1 | K22: 本科12、硕士3、字段与正文不一致2、未写1、博士1 | L22: 计算机类5、不限专业4、电子信息类3、临床医学类3、机械类2、生物科学类2、生物医学工程类2、工商管理类2、自动化类1、医学技术类1、电气类1、管理科学与工程类1、基础医学类1、护理学类1、统计学类1、金融学类1、经济学类1、财政学类1 | M22: 进行用户需求调研和用户行为分析，收集和整理用户反债和数据，为产品设计提供支持 ,参与Ai产品的需求分析、设计和开发工作，协助团队完成产品功能的优化和选代 参与产品选代优化，发现和解决产品中的问题，提高产品质量和用户体验 | N22: jd_only_draft | O22: 从业者一手分享：未找到可入卡的已核正文，缺2名不同作者 日常体验、考核指标、发展路径与条件化风险：缺从业者证据，不用招聘宣传补齐 | P22: https://campus.niuqizp.com/job-v885Cna5n.html
A23: 22 | B23: 医疗健康 | C23: 医生/医技 | D23: 药剂师 | E23: BOSS分类 | G23: 18 | H23: 18 | I23: =IF(H23<2,"证据少",IF(H23<5,"一般","较多")) | J23: 药师4、药剂师3、中药师2、临床药师2、校招-药师（北京）J544891、药师(J10864)1、中药房中药剂师(J21161)1、药剂科药师11、临床护理|药学部药剂师1、药师岗1、药学部中药房中药师1 | K23: 本科10、硕士3、博士3、大专2 | L23: 药学类12、不限专业4、中药学类4、临床医学类1 | M23: 在科主任和上级指导下，从事临床、科研及各项相关工作 日常工作内容：1、负责对药品管理法和医院药品管理制度的严格执行 负责药品的入库、出库管理 | N23: 未建卡 | P23: https://campus.niuqizp.com/job-v885M5ZNZ.html
A24: 23 | B24: 医疗健康 | C24: 生物医药 | D24: 药物分析 | E24: BOSS分类 | F24: P1 | G24: 18 | H24: 13 | I24: =IF(H24<2,"证据少",IF(H24<5,"一般","较多")) | J24: 分析研究员3、药物分析研究员3、化学药生物分析研究员2、药物分析岗1、2027届-生物分析研究员1、生物药生物分析研究员（上海）(J10990)1、受试物分析研究员1、糖类药物分析1、生物药生物分析研究员1、生物药研发工程师/药物分析工程师1、药物分析人员1、分析研究员-本科1、药物分析人员|质量保证人员1 | K24: 硕士9、本科8、字段与正文不一致1 | L24: 药学类13、生物工程类3、生物科学类3、不限专业3、化学类1、法学类1 | M24: 负责生物样本LC-MS/MS方法开发、验证及样品的定量或者半定量分析 分析临床前小分子样本 起草研究报告,包括试验开发、验证、样品分析报告 | N24: jd_only_draft | O24: 从业者一手分享：未找到可入卡的已核正文，缺2名不同作者 日常体验、考核指标、发展路径与条件化风险：缺从业者证据，不用招聘宣传补齐 | P24: https://campus.niuqizp.com/job-v8k5ZNMnn.html
A25: 24 | B25: 医疗健康 | C25: 临床试验 | D25: 临床协调员 | E25: BOSS分类 | F25: P1 | G25: 18 | H25: 13 | I25: =IF(H25<2,"证据少",IF(H25<5,"一般","较多")) | J25: 临床协调员CRC3、临床协调员3、临床研究协调员（CRC）3、临床协调员实习生2、实习临床协调员2、CRC临床协调员|PM项目经理|BD专员1、CRC临床研究协调员1、临床协调员实习生-成都公卫1、2027届临床协调员CRC1、临床协调员实习生-云南省肿瘤医院1 | K25: 本科12、大专6 | L25: 护理学类9、临床医学类8、药学类6、不限专业4、基础医学类1、生物科学类1、工商管理类1、生物工程类1 | M25: 根据GCP和研究方案要求，协助项目负责医生完成临床试验各项非医学判断工作 协助研究者进行试验参与者筛选、入组及随访工作 协助完成文件递交及研究资料的收集、归档和管理工作 | N25: jd_plus_scoped_practitioners | O25: metrics未找到可入卡本人经历证据，留空 | P25: https://campus.niuqizp.com/job-v885nazzz.html
A26: 25 | B26: 电子/电气/通信 | C26: 电气/自动化 | D26: 自动化工程师 | E26: BOSS分类 | F26: P2 | G26: 18 | H26: 17 | I26: =IF(H26<2,"证据少",IF(H26<5,"一般","较多")) | J26: 自动化工程师12、电气与自动化工程师2、自动化工程师（长沙）1、电气自动化工程师（地点 宜昌）1、电气自动化工程师1、2026招聘自动化工程师1 | K26: 本科9、硕士4、未写3、大专2 | L26: 电气类8、自动化类4、机械类4、不限专业3、材料类1、设计学类1 | M26: 新项目导入新产品上线，评估自动化方案 协助设备厂商安装、调试自动化设备 编写设备操作SOP，对产线员工/QC做设备培训 | N26: jd_only_draft | O26: 从业者一手分享：未找到可入卡的已核正文，缺2名不同作者 日常体验、考核指标、发展路径与条件化风险：缺从业者证据，不用招聘宣传补齐 | P26: https://campus.niuqizp.com/job-v885MntCZ.html
A27: 26 | B27: 人力/行政/法务 | C27: 人力资源 | D27: 人力资源专员/助理 | E27: BOSS分类 | F27: P2 | G27: 17 | H27: 16 | I27: =IF(H27<2,"证据少",IF(H27<5,"一般","较多")) | J27: 人力资源岗6、人力资源管理岗3、人力资源管理岗XJXJ1、人力资源管理专员1、人力资源管理1、人力资源管理岗HNSS1、人力资源管理类（哈尔滨）1、人力资源管理职位1、人力资源储备干部（27届）1、人力资源管理师1 | K27: 本科12、硕士4、字段与正文不一致1 | L27: 不限专业10、工商管理类5、公共管理类1、心理学类1、金融学类1 | M27: 协助人力资源规划与制度体系的落地执行 组织实施人力资源模块相关工作，保障人力供给与管理效能 参与搭建可持续的人力资源管理体系，为公司战略提供人才支撑 | N27: jd_only_draft | O27: 从业者一手分享：未找到可入卡的已核正文，缺2名不同作者 日常体验、考核指标、发展路径与条件化风险：缺从业者证据，不用招聘宣传补齐 | P27: https://campus.niuqizp.com/job-v8YNLNZCL.html
A28: 27 | B28: 金融 | C28: 保险 | D28: 保险理赔 | E28: BOSS分类 | F28: P1 | G28: 16 | H28: 13 | I28: =IF(H28<2,"证据少",IF(H28<5,"一般","较多")) | J28: 理赔岗位（车辆保险方向）2、理赔审核岗2、核保数据管培生2、理赔管理岗1、理赔支持岗（包头市本部）1、理赔部理赔管理岗（人伤方向）（所属河北分公司）1、社保理赔岗1、理赔岗（车辆保险方向）1、保险顾问|理赔服务岗1、核保/核赔专员/助理1、理赔类岗位1、理赔管培生1、核保管培生|理赔管培生1 | K28: 本科15、未写1 | L28: 机械类4、不限专业3、金融学类2、交通运输类2、药学类1、生物科学类1、数学类1、物理学类1、土木类1、基础医学类1、法学类1、自动化类1、电气类1、材料类1、动物医学类1、工商管理类1、计算机类1 | M28: 机构理赔数据分析，并制定相应的改善措施 负责理赔规则宣导、问题解释及疑难案件的沟通处理 负责保单基础服务及业务结算、业务续转等工作，统计部门新签协议、投保、续保数据 | N28: jd_only_draft | O28: 从业者一手分享：未找到可入卡的已核正文，缺2名不同作者 日常体验、考核指标、发展路径与条件化风险：缺从业者证据，不用招聘宣传补齐 | P28: https://campus.niuqizp.com/job-v8Y5ZCZZZ.html
A29: 28 | B29: 生产制造 | C29: 质量管理 | D29: 实验室/检测技术员 | E29: 招聘样本补充 | F29: P2 | G29: 16 | H29: 14 | I29: =IF(H29<2,"证据少",IF(H29<5,"一般","较多")) | J29: 实验技术员3、细胞培养实验员2、细胞生物实验员1、27届实验室运营培训生(J15293)1、生物技术实验员1、有源医疗器械检验员|食品业务员1、实验员助理1、毒理实验员1、生物学检验员|新材料及医疗器械业务员1、食品检验员1、化学分析技术员1、研究人员|实验技术员1、光学检验员1 | K29: 本科8、大专3、硕士3、未写1、博士1 | L29: 生物科学类5、药学类4、基础医学类3、临床医学类2、不限专业2、土木类1、生物工程类1 | M29: 负责严格按照SOP的要求进行操作，在工作结束后按照要求完成清场 完成实验任务，提交完整的实验报告，分析存在的问题并及时修正 对本工序的产品质量和工作质量负责 | N29: jd_only_draft | O29: 从业者一手分享：未找到可入卡的已核正文，缺2名不同作者 日常体验、考核指标、发展路径与条件化风险：缺从业者证据，不用招聘宣传补齐 可核职责少于4条，不凑数 | P29: https://campus.niuqizp.com/job-v8U5aZ5tN.html
A30: 29 | B30: 医疗健康 | C30: 医生/医技 | D30: 内科医生 | E30: BOSS分类 | G30: 15 | H30: 14 | I30: =IF(H30<2,"证据少",IF(H30<5,"一般","较多")) | J30: 内科医师4、内科医师岗2、内科医生2、脑血管病内科医师1、呼吸内科医师1、心内科医师1、内科医师-2027届高校毕业生1、心血管内科医师（2027年校招）1、内科医生（2027届）-厦门鹭园1、心血管内科医师1 | K30: 硕士9、本科3、字段与正文不一致2、博士1 | L30: 临床医学类12、社会学类1、不限专业1 | M30: 负责内科常见病、多发病的临床诊断、治疗及病历书写工作，确保医疗文书规范完整 严格执行三级查房制度，参与科室疑难病例讨论与会诊，协助上级医师制定诊疗方案 密切观察患者病情变化，及时处理突发状况，保障医疗安全与质量 | N30: 未建卡 | P30: https://campus.niuqizp.com/job-v8YNL5Lza.html
A31: 30 | B31: 医疗健康 | C31: 医生/医技 | D31: 验光师 | E31: BOSS分类 | G31: 15 | H31: 15 | I31: =IF(H31<2,"证据少",IF(H31<5,"一般","较多")) | J31: 验光师10、2026招聘店员|加工师|验光师1、管培生|储备验光师1、眼镜验光师1、眼科视光师|验光师|儿科评估师1、高级验光师1 | K31: 大专9、本科4、未写2 | L31: 不限专业7、医学技术类2、临床医学类1 | M31: 完成客观、主觉等全流程验光，采集相关信息 开展视功能评估，针对异常给出矫正与训练建议 做好设备日常维保，发现故障及时上报处理 | N31: 未建卡 | P31: https://campus.niuqizp.com/job-v8l5CZnLt.html
A32: 31 | B32: 医疗健康 | C32: 医生/医技 | D32: 医生助理 | E32: BOSS分类 | G32: 14 | H32: 14 | I32: =IF(H32<2,"证据少",IF(H32<5,"一般","较多")) | J32: 医生助理6、医疗助理5、医师助理1、医疗助理员1、宠物医生助理1 | K32: 本科8、大专5、未写1 | L32: 基础医学类5、临床医学类4、医学技术类2、中医学类1、公共管理类1、动物医学类1、护理学类1、不限专业1 | M32: 负责专家的日常沟通服务，确保专家出诊的后勤保障工作 收集专家出诊期间的相关需求，并跟进落实 负责医院住院患者的随访工作 | N32: 未建卡 | P32: https://campus.niuqizp.com/job-v8y5tzC5n.html
A33: 32 | B33: 医疗健康 | C33: 生物医药 | D33: 制剂研发 | E33: BOSS分类 | F33: P1 | G33: 14 | H33: 12 | I33: =IF(H33<2,"证据少",IF(H33<5,"一般","较多")) | J33: 制剂研究员5、制剂研发员2、外用制剂开发研究员1、制剂开发科学家1、制剂研发1、药物制剂研发1、中药制剂开发研究员1、化药药物制剂研发1、制剂开发工程师1 | K33: 硕士5、博士4、字段与正文不一致2、本科2、未写1 | L33: 药学类4、不限专业3、生物科学类2、化工与制药类2、机械类1、生物工程类1 | M33: 负责项目工艺研究，包括处方筛选、工艺优化、包材选择、稳定性考察等 完成上级领导交办的其它工作 进行处方筛选与工艺优化，确保制剂的稳定性、生物利用度和可放大性 | N33: jd_only_draft | O33: 从业者一手分享：未找到可入卡的已核正文，缺2名不同作者 日常体验、考核指标、发展路径与条件化风险：缺从业者证据，不用招聘宣传补齐 | P33: https://campus.niuqizp.com/job-v8Y5CatM5.html
A34: 33 | B34: 医疗健康 | C34: 医疗销售 | D34: 健康顾问 | E34: BOSS分类 | F34: P1 | G34: 14 | H34: 14 | I34: =IF(H34<2,"证据少",IF(H34<5,"一般","较多")) | J34: 健康顾问9、口腔健康顾问1、产品健康顾问1、健康顾问（免费住宿、晋升空间大）1、中医健康顾问1、前台咨询|研发助理|健康顾问|市场运营1 | K34: 大专11、未写2、本科1 | L34: 不限专业5、护理学类5、药学类4、医学技术类4、食品科学与工程类3、公共卫生与预防医学类2、临床医学类2、中医学类2、工商管理类1、电子商务类1 | M34: 岗位职责1、负责到店客户接待、健康咨询服务 协调、确定治疗方案，达成患者转化、成交 对于未成交患者，和患者讨论该方案的好处和潜在未治疗，并跟进回访 | N34: jd_only_draft | O34: 从业者一手分享：未找到可入卡的已核正文，缺2名不同作者 日常体验、考核指标、发展路径与条件化风险：缺从业者证据，不用招聘宣传补齐 | P34: https://campus.niuqizp.com/job-v8lNLZazC.html
A35: 34 | B35: 医疗健康 | C35: 生物医药 | D35: 药物合成 | E35: BOSS分类 | F35: P1 | G35: 13 | H35: 11 | I35: =IF(H35<2,"证据少",IF(H35<5,"一般","较多")) | J35: 合成研究员4、药化合成研究员3、有机合成研究员2、初级合成研究员1、化学合成研究员1、药物合成工作人员1、药物合成分析研究员1 | K35: 硕士9、本科2、博士1、字段与正文不一致1 | L35: 药学类6、化工与制药类3、不限专业2、化学类1、材料类1 | M35: 从事药物合成相关工作，协助有机合成化合物的研发 按要求进行实验记录以及独立分析、解决实验问题 完成公司研发项目及订单生产 | N35: jd_only_draft | O35: 从业者一手分享：未找到可入卡的已核正文，缺2名不同作者 日常体验、考核指标、发展路径与条件化风险：缺从业者证据，不用招聘宣传补齐 | P35: https://campus.niuqizp.com/job-v885MLCzC.html
A36: 35 | B36: 互联网/AI | C36: 技术项目管理 | D36: 项目经理/主管 | E36: BOSS分类 | F36: P2 | G36: 13 | H36: 11 | I36: =IF(H36<2,"证据少",IF(H36<5,"一般","较多")) | J36: 生产项目经理2、项目经理1、石嘴山分公司-项目经理1、东莞分公司-项目经理1、公共绩效与信息化研究中心项目主管1、项目经理（2027届校招）1、项目主管,见习生,项目实习生,传播实习生,行政实习生,社工服务站主任,社工服务站副主任,社工服务站片长,社工服务站一线社工,社工服务站社工助理1、项目主管岗位1、项目经理(英语/日语/韩语)1、研发项目经理1、医药客户项目经理1、项目经理（商务人员）1 | K36: 本科5、博士3、硕士3、大专1、未写1 | L36: 不限专业4、临床医学类2、药学类2、经济学类1、统计学类1、心理学类1、公共管理类1、社会学类1、新闻传播学类1、公共卫生与预防医学类1、化学类1、工商管理类1、基础医学类1 | M36: 负责研发项目全周期管理，统筹规划、执行与跟踪，保障项目按期推进 协调内外部资源，跟进原料药合成、制剂、质量研究进度，汇总项目数据 参与技术转移、工艺优化，协助 CTD 等申报资料整理撰写 | N36: jd_only_draft | O36: 从业者一手分享：未找到可入卡的已核正文，缺2名不同作者 日常体验、考核指标、发展路径与条件化风险：缺从业者证据，不用招聘宣传补齐 | P36: https://campus.niuqizp.com/job-vU85Caa5t.html
A37: 36 | B37: 客服/运营 | C37: 内容运营 | D37: 新媒体运营 | E37: BOSS分类 | F37: P2 | G37: 13 | H37: 13 | I37: =IF(H37<2,"证据少",IF(H37<5,"一般","较多")) | J37: 新媒体运营7、新媒体运营实习编辑,研究员助理实习生2、社交媒体部新媒体运营实习生1、文科教师|理科教师|教育主播|新媒体运营专员1、新媒体运营实习生1、网络新媒体运营1 | K37: 本科10、大专2、未写1 | L37: 不限专业4、新闻传播学类3、经济学类2、法学类2、社会学类2、戏剧与影视学类2、心理学类1、历史学类1、中国语言文学类1、计算机类1、设计学类1、美术学类1、音乐与舞蹈学类1、工商管理类1 | M37: 岗位职责：撰写策划方案，协助新媒体产品制作，支持重点项目 统筹视频更新、政策更新、意向用户线索跟进等多项任务，确保工作节奏有序、不遗漏 研究员助理实习生（2 - 4名）：协助研究员进行课题的资料收集等基础研究工作 | N37: jd_only_draft | O37: 从业者一手分享：未找到可入卡的已核正文，缺2名不同作者 日常体验、考核指标、发展路径与条件化风险：缺从业者证据，不用招聘宣传补齐 | P37: https://campus.niuqizp.com/job-v885ztNZa.html
A38: 37 | B38: 教育培训 | C38: 教师 | D38: 英语教师 | E38: BOSS分类 | F38: P2 | G38: 13 | H38: 12 | I38: =IF(H38<2,"证据少",IF(H38<5,"一般","较多")) | J38: 英语老师4、英语教师4、双语小学部、初中--双语数学教师、英语教师、外籍教师1、青少英语教师(国际教育)1、小学英语老师1、小学部--语文教师、数学教师、英语教师、外籍教师1、小学英语教师1 | K38: 本科11、硕士2 | L38: 不限专业7、外国语言文学类1 | M38: 外籍教师注重营造真实语言环境，参与英语活动、课程开发与资源建设 参与教研、集体备课、听课评课、命题评估、教学质量分析及课程资源建设 关注学生个体差异，做好学习指导、习惯培养与家校沟通，配合班级管理及学校活动 | N38: jd_only_draft | O38: 从业者一手分享：未找到可入卡的已核正文，缺2名不同作者 日常体验、考核指标、发展路径与条件化风险：缺从业者证据，不用招聘宣传补齐 | P38: https://campus.niuqizp.com/job-v8UNLNMCC.html
A39: 38 | B39: 房地产/建筑 | C39: 工程管理 | D39: 工程造价 | E39: BOSS分类 | F39: P2 | G39: 13 | H39: 10 | I39: =IF(H39<2,"证据少",IF(H39<5,"一般","较多")) | J39: 工程造价-园林古建工程1、工程造价师1、工程造价咨询工程师-乌鲁木齐1、工程造价工程师1、工程造价岗1、水务-工程造价1、电力工程造价员1、工程造价1、工程造价工程技术人员1、工程造价-北京1、工程造价-上海1、工程造价专员1、工程造价岗-城建一公司1 | K39: 本科10、硕士2、大专1 | L39: 不限专业6、管理科学与工程类5、电气类1 | M39: 岗位职责： 1、承担项目成本分析，保证项目收益，管理项目工程量计算、预算报价 参与项目合同的谈判、评审、签订与交底，合理转移总包风险 负责项目经营报价、进度款审核、结算及工程竣工结算 | N39: jd_only_draft | O39: 从业者一手分享：未找到可入卡的已核正文，缺2名不同作者 日常体验、考核指标、发展路径与条件化风险：缺从业者证据，不用招聘宣传补齐 | P39: https://campus.niuqizp.com/job-vYm5ananM.html
A40: 39 | B40: 医疗健康 | C40: 医生/医技 | D40: 皮肤科医生 | E40: BOSS分类 | G40: 12 | H40: 12 | I40: =IF(H40<2,"证据少",IF(H40<5,"一般","较多")) | J40: 皮肤科医师2、皮肤科2、皮肤科住院医师(J10855)1、皮肤科医师（医美部）医师1、皮肤科医生1、皮肤科住院医师1、皮肤科医生(J21159)1、2027招聘皮肤科医师1、皮肤科中西医结合医师1、皮肤科医师（2027年校招）1 | K40: 硕士8、博士2、未写2 | L40: 临床医学类9、社会学类1、不限专业1、中医学类1 | M40: 在科主任领导和主治医师指导下对病患进行检查、诊断、治疗，开写医嘱并检查其执行情况 负责书写病患住院期间的病程记录，及时完成出院病员的病案小结 向主治医师及时报告诊断、治疗上的困难以及病患病情的变化，提出需要转科或出院的意见 | N40: 未建卡 | P40: https://campus.niuqizp.com/job-vUm5MZCza.html
...

Sheet 样本明细
A1: 样本ID | B1: 挂到的岗位节点 | C1: 匹配方式 | D1: 原始岗位名 | E1: 单位 | F1: 专业类 | G1: 专业来源 | H1: 学历 | I1: 学历字段冲突 | J1: 发布日期 | K1: 信息来源 | L1: 链接 | M1: 归类判断 | N1: 应归到
A2: vky5C5ZC5 | B2: 互联网/AI › 人工智能 › 人工智能工程师（未细分） | C2: 关键词 | D2: 人工智能工程师 | E2: 北京海博思创科技股份有限公司 | F2: 计算机类、电子信息类 | G2: 需求专业字段 | H2: 硕士 | J2: 2026-09-08 | K2: 内蒙古工业大学 | L2: https://campus.niuqizp.com/job-vky5C5ZC5.html
A3: vmm5MZ5MC | B3: 互联网/AI › 人工智能 › 人工智能工程师（未细分） | C3: 关键词 | D3: 人工智能工程师 | E3: 北京中电普华信息技术有限公司 | F3: 不限专业 | G3: 需求专业字段 | H3: 硕士 | J3: 2026-09-24 | K3: 南开大学 | L3: https://campus.niuqizp.com/job-vmm5MZ5MC.html
A4: vrm5ntZZL | B4: 互联网/AI › 人工智能 › 人工智能工程师（未细分） | C4: 关键词 | D4: 人工智能工程师 | E4: 中国大百科全书出版社有限公司 | F4: 计算机类 | G4: 需求专业字段 | H4: 硕士 | J4: 2026-09-16 | K4: 国聘 | L4: https://campus.niuqizp.com/job-vrm5ntZZL.html
A5: vwy5ZLz5M | B5: 互联网/AI › 人工智能 › 人工智能工程师（未细分） | C5: 关键词 | D5: 人工智能工程师 | E5: 华信永道（北京）科技股份有限公司 | F5: 金融学类、经济学类、计算机类、统计学类 | G5: 职责原文 | H5: 硕士 | J5: 2026-03-11 | K5: 河北工业大学 | L5: https://campus.niuqizp.com/job-vwy5ZLz5M.html
A6: vsy5azn5M | B6: 互联网/AI › 人工智能 › 人工智能工程师（未细分） | C6: 关键词 | D6: 人工智能工程师-27届校招 | E6: 卓望数码技术（深圳）有限公司 | F6: 不限专业 | G6: 需求专业字段 | H6: 本科 | J6: 2026-09-04 | K6: 国家大学生就业服务平台 | L6: https://campus.niuqizp.com/job-vsy5azn5M.html
A7: vyk5CNZLa | B7: 互联网/AI › 人工智能 › 人工智能工程师（未细分） | C7: 关键词 | D7: 人工智能工程师-27届校招（北京、广州） | E7: 卓望数码技术（深圳）有限公司 | F7: 计算机类、数学类 | G7: 需求专业字段 | H7: 本科 | J7: 2026-09-08 | K7: 华中农业大学 | L7: https://campus.niuqizp.com/job-vyk5CNZLa.html
A8: vky5Mttnn | B8: 互联网/AI › 人工智能 › 人工智能工程师（未细分） | C8: 关键词 | D8: 人工智能工程师（地点 武汉） | E8: 中国船舶集团有限公司第七一〇研究所 | F8: 不限专业 | G8: 需求专业字段 | H8: 博士 | J8: 2026-09-23 | K8: 前程无忧 | L8: https://campus.niuqizp.com/job-vky5Mttnn.html
A9: vlm5nZNNt | B9: 互联网/AI › 人工智能 › 人工智能工程师（未细分） | C9: 关键词 | D9: 建筑设计师,结构工程师,给排水工程师,暖通工程师,能源工程师,电气设计师,景观设计师,室内设计师,城乡规划师,总图设计师,工程管理人员,人工智能工程师,计算机工程师,安全工程师,消防工程师,机械工程师 | E9: 中国建筑设计研究院有限公司2027年应届毕业生 | F9: 计算机类、电气类、机械类、建筑类、管理科学与工程类、设计学类 | G9: 需求专业字段 | H9: 本科 | J9: 2026-09-15 | K9: 中国建筑设计研究院 | L9: https://campus.niuqizp.com/job-vlm5nZNNt.html
A10: vk85CZzzN | B10: 互联网/AI › 人工智能 › 医学AI/生物医学大模型 | C10: 关键词 | D10: 2027届-AIDD研究员 | E10: 上海泓博智源医药股份有限公司 | F10: 不限专业 | G10: 需求专业字段 | H10: 硕士 | J10: 2026-09-10 | K10: 南开大学 | L10: https://campus.niuqizp.com/job-vk85CZzzN.html
A11: vsl5Z5LZC | B11: 互联网/AI › 人工智能 › 医学AI/生物医学大模型 | C11: 关键词 | D11: AIDD研究员 | E11: 上海泓博智源医药股份有限公司 | F11: 药学类 | G11: 平台专业标签 | H11: 博士 | J11: 2026-03-13 | K11: 南开大学 | L11: https://campus.niuqizp.com/job-vsl5Z5LZC.html
A12: v8kNLZMaZ | B12: 互联网/AI › 人工智能 › 医学AI/生物医学大模型 | C12: 关键词 | D12: AIDD科学家 | E12: 杭州阿诺生物医药科技有限公司 | F12: 生物科学类 | G12: 需求专业字段 | H12: 字段与正文不一致 | I12: 是 | J12: 2026-10-04 | K12: 同济大学 | L12: https://campus.niuqizp.com/job-v8kNLZMaZ.html
A13: vYl5M55zN | B13: 互联网/AI › 人工智能 › 医学AI/生物医学大模型 | C13: 关键词 | D13: AI化学高级研究员 | E13: 青葵智造(北京)科技有限公司 | F13: 药学类 | G13: 职责原文 | H13: 博士 | J13: 2026-09-21 | K13: 浙江大学 | L13: https://campus.niuqizp.com/job-vYl5M55zN.html
A14: v8Y5na5NZ | B14: 互联网/AI › 人工智能 › 医学AI/生物医学大模型 | C14: 关键词 | D14: AI医疗反向工程师 | E14: 杭州疡医科技有限公司 | F14: 计算机类 | G14: 需求专业字段 | H14: 硕士 | J14: 2026-09-18 | K14: 中国计量大学 | L14: https://campus.niuqizp.com/job-v8Y5na5NZ.html
A15: vrm5aatLZ | B15: 互联网/AI › 人工智能 › 医学AI/生物医学大模型 | C15: 关键词 | D15: AI医疗大模型应用开发实习生 | E15: 南京普惠恒丰信息科技有限公司 | F15: 不限专业 | G15: 需求专业字段 | H15: 本科 | J15: 2026-09-05 | K15: 实习僧 | L15: https://campus.niuqizp.com/job-vrm5aatLZ.html
A16: vrk5ntMZa | B16: 互联网/AI › 人工智能 › 医学AI/生物医学大模型 | C16: 关键词 | D16: AI医疗行业—数据标注实习生 | E16: 上海宜云健康管理咨询有限公司 | F16: 不限专业 | G16: 需求专业字段 | H16: 未写 | J16: 2026-09-17 | K16: 实习僧 | L16: https://campus.niuqizp.com/job-vrk5ntMZa.html
A17: vYm55aMCZ | B17: 互联网/AI › 人工智能 › 医学AI/生物医学大模型 | C17: 关键词 | D17: 制药知识AI应用推广专员 | E17: 北京尚质合规科技有限公司 | F17: 基础医学类、药学类、化学类 | G17: 需求专业字段 | H17: 本科 | J17: 2025-10-10 | K17: 北京化工大学 | L17: https://campus.niuqizp.com/job-vYm55aMCZ.html
A18: vmk55aMCt | B18: 互联网/AI › 人工智能 › 医学AI/生物医学大模型 | C18: 关键词 | D18: 制药知识AI应用研究员 | E18: 北京尚质合规科技有限公司 | F18: 基础医学类、药学类、化学类、计算机类 | G18: 需求专业字段 | H18: 硕士 | J18: 2025-10-10 | K18: 北京化工大学 | L18: https://campus.niuqizp.com/job-vmk55aMCt.html
A19: vmU5t5zzZ | B19: 互联网/AI › 人工智能 › 医学AI/生物医学大模型 | C19: 关键词 | D19: 医学人工智能临床复合型医师|医学数据治理工程师|医学智能体工程师 | E19: 同济大学附属东方医院 | F19: 临床医学类、生物医学工程类 | G19: 职责原文 | H19: 硕士 | J19: 2026-01-09 | K19: 上海市东方医院 | L19: https://campus.niuqizp.com/job-vmU5t5zzZ.html
A20: manual-role_postings_2026-10-05_claude-22 | B20: 互联网/AI › 人工智能 › 医学AI/生物医学大模型 | C20: 关键词 | D20: 生物医学大模型研发 | E20: 未提供 | F20: 药学类、生物医学工程类、生物科学类、计算机类 | G20: 需求专业字段 | H20: 硕士 | K20: 用户提供 | L20: user-provided://2026-10-06/biomed-llm
A21: vmlNL5Zzn | B21: 互联网/AI › 人工智能 › 图像算法 | C21: BOSS末级名称 | D21: AI图像算法实习生 | E21: 西门子医疗系统有限公司 | F21: 不限专业 | G21: 需求专业字段 | H21: 本科 | J21: 2026-10-01 | K21: 实习僧 | L21: https://campus.niuqizp.com/job-vmlNL5Zzn.html
A22: vls5ztMMz | B22: 互联网/AI › 人工智能 › 大模型算法 | C22: BOSS末级名称 | D22: 2026招聘大模型算法工程师 | E22: 北京医者信息科技有限责任公司2026 | G22: 未写 | H22: 未写 | J22: 2026-06-04 | K22: 北京邮电大学世纪学院 | L22: https://campus.niuqizp.com/job-vls5ztMMz.html
A23: vlY5azazZ | B23: 互联网/AI › 人工智能 › 大模型算法 | C23: BOSS末级名称 | D23: 2027招聘世界模型方向多模态大模型算法工程师 | E23: 北京人形机器人创新中心有限公司2027 | F23: 计算机类 | G23: 职责原文 | H23: 硕士 | J23: 2026-09-03 | K23: 南京邮电大学 | L23: https://campus.niuqizp.com/job-vlY5azazZ.html
A24: vYl5azaaL | B24: 互联网/AI › 人工智能 › 大模型算法 | C24: BOSS末级名称 | D24: VLM方向多模态大模型算法工程师 | E24: 北京人形机器人创新中心有限公司 | G24: 未写 | H24: 字段与正文不一致 | I24: 是 | J24: 2026-09-03 | K24: 南京邮电大学 | L24: https://campus.niuqizp.com/job-vYl5azaaL.html
A25: vyk5CtnNL | B25: 互联网/AI › 人工智能 › 大模型算法 | C25: BOSS末级名称 | D25: 【源点顶尖人才计划】大模型算法工程师(A130665) | E25: 百川智能科技有限公司 | F25: 不限专业 | G25: 需求专业字段 | H25: 硕士 | J25: 2026-09-10 | K25: 实习僧 | L25: https://campus.niuqizp.com/job-vyk5CtnNL.html
A26: v8U5MLntn | B26: 互联网/AI › 人工智能 › 大模型算法 | C26: BOSS末级名称 | D26: 大模型算法工程师 | E26: 深圳乐动机器人股份有限公司B3 | F26: 计算机类 | G26: 需求专业字段 | H26: 字段与正文不一致 | I26: 是 | J26: 2026-09-22 | K26: 智联招聘 | L26: https://campus.niuqizp.com/job-v8U5MLntn.html
A27: vslNLzMC5 | B27: 互联网/AI › 人工智能 › 大模型算法 | C27: BOSS末级名称 | D27: 大模型算法研发 | E27: 公安部交通管理科学研究所 | F27: 计算机类 | G27: 需求专业字段 | H27: 硕士 | J27: 2026-10-05 | K27: 智联招聘 | L27: https://campus.niuqizp.com/job-vslNLzMC5.html
A28: vUm55MtZC | B28: 互联网/AI › 人工智能 › 数据标注/AI训练师 | C28: BOSS末级名称 | D28: AI数据标注 | E28: 北京愈心科技有限公司 | F28: 心理学类 | G28: 职责原文 | H28: 字段与正文不一致 | I28: 是 | J28: 2025-10-17 | K28: 南开大学 | L28: https://campus.niuqizp.com/job-vUm55MtZC.html
A29: vls5MMMML | B29: 互联网/AI › 人工智能 › 数据标注/AI训练师 | C29: BOSS末级名称 | D29: 数据标注 | E29: 保定新秀数字科技产业有限公司 | F29: 不限专业 | G29: 需求专业字段 | H29: 未写 | J29: 2026-09-30 | K29: 猎聘 | L29: https://campus.niuqizp.com/job-vls5MMMML.html
A30: vsY5aMCZt | B30: 互联网/AI › 人工智能 › 数据标注/AI训练师 | C30: BOSS末级名称 | D30: 数据标注员 | E30: 内蒙古古戈尔技术开发有限公司 | F30: 计算机类 | G30: 需求专业字段 | H30: 大专 | J30: 2026-09-07 | K30: 内蒙古机电职业技术学院 | L30: https://campus.niuqizp.com/job-vsY5aMCZt.html
A31: vsk5naLzz | B31: 互联网/AI › 人工智能 › 数据标注/AI训练师 | C31: BOSS末级名称 | D31: 数据标注员 | E31: 上饶市方迈网络科技有限公司 | F31: 计算机类 | G31: 需求专业字段 | H31: 字段与正文不一致 | I31: 是 | J31: 2026-09-18 | K31: 九江科技职业大学 | L31: https://campus.niuqizp.com/job-vsk5naLzz.html
A32: vyr5MNZNM | B32: 互联网/AI › 人工智能 › 数据标注/AI训练师 | C32: BOSS末级名称 | D32: 数据标注员 | E32: 贵州星长征教育科技有限公司 | F32: 不限专业 | G32: 需求专业字段 | H32: 未写 | J32: 2026-09-23 | K32: 猎聘 | L32: https://campus.niuqizp.com/job-vyr5MNZNM.html
A33: vYY5nCzM5 | B33: 互联网/AI › 人工智能 › 数据标注/AI训练师 | C33: BOSS末级名称 | D33: 数据标注师 | E33: 上饶市方迈网络科技有限公司 | F33: 计算机类 | G33: 需求专业字段 | H33: 大专 | J33: 2026-09-19 | K33: 南昌应用技术师范学院 | L33: https://campus.niuqizp.com/job-vYY5nCzM5.html
A34: vkr5Mt5Ln | B34: 互联网/AI › 人工智能 › 数据标注/AI训练师 | C34: BOSS末级名称 | D34: 数据标注师 | E34: 内蒙古启职点人才就业服务有限公司 | F34: 计算机类、电子信息类 | G34: 需求专业字段 | H34: 大专 | J34: 2026-09-23 | K34: 内蒙古财经大学 | L34: https://campus.niuqizp.com/job-vkr5Mt5Ln.html
A35: vym5MMttt | B35: 互联网/AI › 人工智能 › 数据标注/AI训练师 | C35: BOSS末级名称 | D35: 数据标注师 | E35: 上饶市方迈网络科技有限公司 | F35: 计算机类 | G35: 需求专业字段 | H35: 本科 | J35: 2026-09-29 | K35: 上饶职业技术学院 | L35: https://campus.niuqizp.com/job-vym5MMttt.html
A36: vrUNLLaLn | B36: 互联网/AI › 人工智能 › 数据标注/AI训练师 | C36: BOSS末级名称 | D36: 数据标注师AI训练师 | E36: 四梦数据（江西）有限公司 | F36: 法学类、计算机类 | G36: 需求专业字段 | H36: 本科 | J36: 2026-09-30 | K36: 江西省教育评估监测研究院 | L36: https://campus.niuqizp.com/job-vrUNLLaLn.html
A37: vll5anzLn | B37: 互联网/AI › 人工智能 › 数据标注/AI训练师 | C37: BOSS末级名称 | D37: 音乐标注项目-数据标注 | E37: 中洲联创（厦门）科技有限公司 | F37: 戏剧与影视学类、音乐与舞蹈学类 | G37: 需求专业字段 | H37: 本科 | J37: 2026-09-04 | K37: 国家大学生就业服务平台 | L37: https://campus.niuqizp.com/job-vll5anzLn.html
A38: vlkNLLatL | B38: 互联网/AI › 人工智能 › 算法工程师 | C38: BOSS末级名称 | D38: 人工智能算法工程师 | E38: 香港中文大学（深圳）城市地下空间及能源研究院 | F38: 计算机类、数学类 | G38: 需求专业字段 | H38: 硕士 | J38: 2026-09-30 | K38: 内蒙古自治区高校学生就业创业服务中心 | L38: https://campus.niuqizp.com/job-vlkNLLatL.html
A39: vYU5NLZaa | B39: 互联网/AI › 人工智能 › 算法工程师 | C39: BOSS末级名称 | D39: 医学研究型PM|医用人工智能算法工程师|转移转化与投资经理 | E39: 上海临床创新转化研究院有限公司 | F39: 基础医学类、临床医学类、中医学类、药学类、生物科学类、计算机类、自动化类、数学类、统计学类、物理学类 | G39: 需求专业字段 | H39: 硕士 | J39: 2025-10-22 | K39: 高校人才网 | L39: https://campus.niuqizp.com/job-vYU5NLZaa.html
A40: v8k5MZz5M | B40: 互联网/AI › 人工智能 › 算法工程师 | C40: BOSS末级名称 | D40: 图像与图谱算法工程师（地点 宜昌） | E40: 中国船舶集团有限公司第七一〇研究所 | F40: 不限专业 | G40: 需求专业字段 | H40: 硕士 | J40: 2026-09-24 | K40: 前程无忧 | L40: https://campus.niuqizp.com/job-v8k5MZz5M.html
...

Sheet 专业连线
A1: 专业类 | B1: 行业 | C1: 岗位 | D1: 样本数 | E1: 单位数 | F1: 证据强度 | G1: 仅平台标签样本 | H1: 学历分布 | I1: 示例链接 | J1: 连线判断 | K1: 问题说明
A2: 不限专业 | B2: 医疗健康 | C2: 临床医生（科室未细分） | D2: 15 | E2: 13 | F2: =IF(E2<2,"证据少",IF(E2<5,"一般","较多")) | G2: 0 | H2: 硕士6、本科5、未写3、博士1 | I2: https://campus.niuqizp.com/job-v8kNLzzM5.html
A3: 不限专业 | B3: 医疗健康 | C3: 医疗产品技术支持 | D3: 11 | E3: 11 | F3: =IF(E3<2,"证据少",IF(E3<5,"一般","较多")) | G3: 0 | H3: 本科6、硕士4、未写1 | I3: https://campus.niuqizp.com/job-v8s5nNntZ.html
A4: 不限专业 | B4: 人力/行政/法务 | C4: 人力资源专员/助理 | D4: 10 | E4: 9 | F4: =IF(E4<2,"证据少",IF(E4<5,"一般","较多")) | G4: 0 | H4: 本科8、字段与正文不一致1、硕士1 | I4: https://campus.niuqizp.com/job-v8YNLNZCL.html
A5: 不限专业 | B5: 市场/公关/广告 | C5: 市场营销策划 | D5: 9 | E5: 9 | F5: =IF(E5<2,"证据少",IF(E5<5,"一般","较多")) | G5: 0 | H5: 未写4、本科4、字段与正文不一致1 | I5: https://campus.niuqizp.com/job-v8Y5ztLNL.html
A6: 不限专业 | B6: 医疗健康 | C6: 医药代表 | D6: 12 | E6: 7 | F6: =IF(E6<2,"证据少",IF(E6<5,"一般","较多")) | G6: 0 | H6: 本科11、大专1 | I6: https://campus.niuqizp.com/job-v8U5MMtNN.html
A7: 不限专业 | B7: 生产制造 | C7: 机械工程师 | D7: 7 | E7: 7 | F7: =IF(E7<2,"证据少",IF(E7<5,"一般","较多")) | G7: 0 | H7: 本科4、硕士2、大专1 | I7: https://campus.niuqizp.com/job-vUYNLNzLa.html
A8: 不限专业 | B8: 医疗健康 | C8: 验光师 | D8: 7 | E8: 7 | F8: =IF(E8<2,"证据少",IF(E8<5,"一般","较多")) | G8: 0 | H8: 大专7 | I8: https://campus.niuqizp.com/job-vUk5Mazza.html
A9: 不限专业 | B9: 高级管理 | C9: 管理培训生 | D9: 15 | E9: 6 | F9: =IF(E9<2,"证据少",IF(E9<5,"一般","较多")) | G9: 0 | H9: 本科10、硕士5 | I9: https://campus.niuqizp.com/job-vUlNLNtCN.html
A10: 不限专业 | B10: 教育培训 | C10: 英语教师 | D10: 7 | E10: 6 | F10: =IF(E10<2,"证据少",IF(E10<5,"一般","较多")) | G10: 0 | H10: 本科7 | I10: https://campus.niuqizp.com/job-v8UNLNMCC.html
A11: 不限专业 | B11: 房地产/建筑 | C11: 工程造价 | D11: 6 | E11: 6 | F11: =IF(E11<2,"证据少",IF(E11<5,"一般","较多")) | G11: 0 | H11: 本科4、硕士1、大专1 | I11: https://campus.niuqizp.com/job-vYm5ananM.html
A12: 不限专业 | B12: 医疗健康 | C12: 健康顾问 | D12: 5 | E12: 5 | F12: =IF(E12<2,"证据少",IF(E12<5,"一般","较多")) | G12: 0 | H12: 大专2、未写2、本科1 | I12: https://campus.niuqizp.com/job-v8lNLZazC.html
A13: 不限专业 | B13: 教育培训 | C13: 教师 | D13: 5 | E13: 4 | F13: =IF(E13<2,"证据少",IF(E13<5,"一般","较多")) | G13: 0 | H13: 本科3、字段与正文不一致1、大专1 | I13: https://campus.niuqizp.com/job-v8Y5n5nnC.html
... A893: 马克思主义理论类 | B893: 高级管理 | C893: 管理培训生 | D893: 1 | E893: 1 | F893: =IF(E893<2,"证据少",IF(E893<5,"一般","较多")) | G893: 0 | H893: 硕士1 | I893: https://campus.niuqizp.com/job-vlk5aNa5N.html
